Workbook

Sheet 1_Cover
B2: INDIE FILM FINANCE PLAN
B3: $2,000,000 Production Budget | $1,040,000 Equity Raise | Single-Film LLC | [PROJECT TITLE]
B5: PROJECT SNAPSHOT — Edit yellow/blue cells to customize
B6: Film Title | C6: [PROJECT TITLE]
B7: Genre | C7: [e.g. Thriller / Drama / Horror]
B8: Director | C8: [DIRECTOR NAME]
B9: Producer | C9: [PRODUCER NAME]
B10: Key Cast | C10: [LEAD ACTOR / TBD]
B11: Sales Agent | C11: [TBD]
B12: Shoot State | C12: [STATE — drives tax credit %]
B13: Schedule | C13: 30-Day Principal Photography, Digital 4K
B14: Festival Target | C14: Sundance / SXSW / Tribeca
B15: Production Start | C15: Q3 2026
B16: Delivery | C16: Q1 2027
B17: Rating | C17: R / PG-13
B19: FINANCING SUMMARY (Auto-calculates from Assumptions)
B20: Total Budget | C20: ='2_Assumptions'!C7
B21: Equity Being Raised | C21: ='2_Assumptions'!C12
B22: Tax Credit (Rebate) | C22: ='2_Assumptions'!C8
B23: Senior Debt | C23: ='2_Assumptions'!C9
B24: Gap / Mezz | C24: ='2_Assumptions'!C10
B25: Min. Investment / Investor | C25: ='2_Assumptions'!C14
B26: Recoupment Premium | C26: ='2_Assumptions'!C17
B27: Investor Backend | C27: ='2_Assumptions'!C18
B28: Raise Close | C28: ='2_Assumptions'!C32
B29: Legal Vehicle | C29: ='2_Assumptions'!C33
B31: SHEET NAVIGATOR
B32: 2_Assumptions | C32: Master inputs — start here to customize for your project
B33: 3_Budget | C33: Full production budget by department: ATL, BTL, Post, G&A, contingency
B34: 4_Capital_Stack | C34: All financing sources, risk positions, and investor terms at a glance
B35: 5_Waterfall | C35: Revenue waterfall — complete investor return calculator
B36: 6_Revenue_Model | C36: Distribution window revenue: Conservative / Base / Upside scenarios
B37: 7_Cash_Flow | C37: Monthly cash flow: capital deployment and distribution proceeds timeline
B38: 8_Sensitivity | C38: ROI / MOIC / IRR sensitivity matrices
B39: 9_Risk_Register | C39: Risk factors, probability, impact, and mitigation strategies
B41: COLOR LEGEND
B42: Blue = Input | C42: Change to customize
B43: Black = Formula | C43: Do not edit
B44: Green = Cross-Sheet Link | C44: Pulls from another tab
B45: Yellow Background | C45: Key assumption to review
...

Sheet 2_Assumptions
B2: MASTER ASSUMPTIONS — Change blue cells; all other sheets update automatically
B3: Assumption | C3: Value | D3: Notes | E3: Benchmark
B4: A. PROJECT & BUDGET
B5: Project Title | C5: [PROJECT TITLE] | D5: Your film title as it appears in legal docs | E5: —
B6: Genre | C6: [e.g. Thriller] | D6: Drives comparable film selection | E6: —
B7: Total Production Budget ($) | C7: 2000000 | D7: All-in: ATL + BTL + Post + G&A + Bond + Contingency | E7: $500K–$10M
B8: State Tax Credit / Rebate ($) | C8: 400000 | D8: ~20-35% qualifying in-state spend; received post-wrap | E8: 20-45% of budget
B9: Senior Debt – Tax Credit Loan ($) | C9: 360000 | D9: 90% advance on tax credit; first-position lien on credit proceeds | E9: 90% × credit
B10: Gap / Mezz Financing ($) | C10: 0 | D10: Second-position; use only if needed to close gap; avoid at $750K | E10: 0-15% of budget
B11: Pre-Sale Loan ($) | C11: 0 | D11: Against executed MG contracts; viable at $2M+ with sales agent | E11: 0-20% at $2M+
B12: TOTAL EQUITY RAISE ($) | C12: =C7-C9-C10-C11-C8 | D12: Budget minus all debt/soft money = equity needed from investors | E12: Auto
B13: Est. # of Investors | C13: 10 | D13: Divide equity / min. investment for rough count | E13: 5-30 typical
B14: Min. Investment Per Investor ($) | C14: 50000 | D14: Reg D 506(b) accredited investor minimum | E14: $25K-$100K
B16: B. INVESTOR TERMS & WATERFALL
B17: Investor Recoupment Premium (%) | C17: 0.2 | D17: % above principal before backend; typ. 15-25% | E17: 15%-25%
B18: Backend Split — Investor Pool (%) | C18: 0.5 | D18: % of net profit after hurdle; other 50% to producer | E18: 40%-50%
B19: Backend Split — Producer (%) | C19: =1-C18 | D19: Auto-calculated from investor split | E19: Auto
B20: Senior Debt Interest Rate | C20: 0.09 | D20: Tax credit bridge; 8-12% typical | E20: 8%-12%
B21: Gap Loan Interest Rate | C21: 0.16 | D21: Higher risk; 12-20% for gap lenders | E21: 12%-20%
B22: Loan Term (months) | C22: 18 | D22: Bridge to distribution receipt; affects IRR | E22: 12-36 months
B24: C. DISTRIBUTION ASSUMPTIONS (used in Waterfall & Revenue Model)
B25: Distribution Strategy | C25: Limited Theatrical + SVOD | D25: Drives P&A and distributor fee structure | E25: —
B26: Exhibitor / Theater Split (%) | C26: 0.5 | D26: Theaters retain ~50-55% of theatrical gross | E26: 45%-55%
B27: P&A / Marketing Budget ($) | C27: 150000 | D27: Recouped before any commissions | E27: $50K-$2M+
B28: Distribution Fee (%) | C28: 0.3 | D28: % of net film rental; negotiable | E28: 25%-35%
B29: Sales Agent Commission (%) | C29: 0.12 | D29: % of gross foreign receipts | E29: 10%-15%
B30: CAMA (Collection Account)? | C30: Yes | D30: Strongly recommended — protects waterfall order | E30: Yes (best practice)
B31: Completion Bond Required? | C31: Yes | D31: Required by most gap/debt providers; ~2-3% in budget | E31: Yes if debt used
B33: D. LEGAL, OFFERING & TIMELINE
B34: Raise Close Target | C34: Q2 2026 | D34: Investment deadline for pitch materials | E34: —
B35: Legal Vehicle | C35: Single-Purpose LLC | D35: Investors = Class A Limited Members; filmmaker = Manager | E35: LLC (SPE)
B36: Securities Exemption | C36: Reg D / Rule 506(b) | D36: Accredited investors only; no general solicitation (or 506(c) w/ verification) | E36: Reg D
B37: PPM Required? | C37: Yes — Attorney Drafted | D37: Legally binding; must be completed before accepting any funds | E37: Always
B38: SAG-AFTRA Tier | C38: Modified Low Budget | D38: Confirm eligibility; drives all cast minimum rates | E38: Budget-dependent
B39: E&O Insurance ($) | C39: 1000000 | D39: Required by all major distributors at delivery | E39: $1M minimum

Sheet 3_Budget
B2: PRODUCTION BUDGET — Top Sheet by Department | $2M Example | Blue = input, Black = formula
B3: Line Item | C3: Budget ($) | D3: % Total | E3: Prior Est. ($) | F3: Variance ($) | G3: Notes
B4: ABOVE THE LINE
B5: Story & Rights / Option | C5: 40000 | D5: =IF(C44=0,"",C5/C44) | E5: 40000 | F5: =C5-E5 | G5: Option on underlying IP rights
B6: Screenplay / Final Polish | C6: 25000 | D6: =IF(C44=0,"",C6/C44) | E6: 25000 | F6: =C6-E6 | G6: WGA minimum or negotiated fee
B7: Producer(s) Fee | C7: 60000 | D7: =IF(C44=0,"",C7/C44) | E7: 60000 | F7: =C7-E7 | G7: Lead producer; deferral common
B8: Director Fee | C8: 100000 | D8: =IF(C44=0,"",C8/C44) | E8: 100000 | F8: =C8-E8 | G8: DGA or non-union negotiated
B9: Lead Cast | C9: 200000 | D9: =IF(C44=0,"",C9/C44) | E9: 200000 | F9: =C9-E9 | G9: SAG Modified Low Budget rates
B10: Supporting Cast | C10: 50000 | D10: =IF(C44=0,"",C10/C44) | E10: 50000 | F10: =C10-E10 | G10: Supporting & day players
B11: ATL SUBTOTAL | C11: =SUM(C5,C6,C7,C8,C9,C10) | D11: =IF(C44=0,"",C11/C44)
B12: BELOW THE LINE — PRODUCTION
B13: 1st AD / Production Staff | C13: 35000 | D13: =IF(C44=0,"",C13/C44) | E13: 35000 | F13: =C13-E13 | G13: Dept coordinators + PAs
B14: Camera (crew + equipment) | C14: 80000 | D14: =IF(C44=0,"",C14/C44) | E14: 80000 | F14: =C14-E14 | G14: DP + camera package + lenses
B15: Grip & Electric | C15: 120000 | D15: =IF(C44=0,"",C15/C44) | E15: 120000 | F15: =C15-E15 | G15: Gaffer, key grip, truck + equip.
B16: Art Dept / Production Design | C16: 90000 | D16: =IF(C44=0,"",C16/C44) | E16: 90000 | F16: =C16-E16 | G16: PD, set dec, props, builds
B17: Wardrobe / Costume | C17: 35000 | D17: =IF(C44=0,"",C17/C44) | E17: 35000 | F17: =C17-E17 | G17: Costumes, rentals, laundry
B18: Hair & Makeup | C18: 28000 | D18: =IF(C44=0,"",C18/C44) | E18: 28000 | F18: =C18-E18 | G18: Key MUA + hair dept
B19: Sound (Production) | C19: 22000 | D19: =IF(C44=0,"",C19/C44) | E19: 22000 | F19: =C19-E19 | G19: Mixer, boom, kit rental
B20: Locations & Permits | C20: 65000 | D20: =IF(C44=0,"",C20/C44) | E20: 65000 | F20: =C20-E20 | G20: Location fees, scouts, permits
B21: Transportation | C21: 55000 | D21: =IF(C44=0,"",C21/C44) | E21: 55000 | F21: =C21-E21 | G21: Trucks, base camp, talent
B22: Catering & Craft Services | C22: 40000 | D22: =IF(C44=0,"",C22/C44) | E22: 40000 | F22: =C22-E22 | G22: On-set food ~30 days
B23: Extras / Background | C23: 18000 | D23: =IF(C44=0,"",C23/C44) | E23: 18000 | F23: =C23-E23 | G23: Featured + general BG
B24: Stunts | C24: 15000 | D24: =IF(C44=0,"",C24/C44) | E24: 15000 | F24: =C24-E24 | G24: Stunt coordinator + personnel
B25: BTL PRODUCTION SUBTOTAL | C25: =SUM(C13,C14,C15,C16,C17,C18,C19,C20,C21,C22,C23,C24) | D25: =IF(C44=0,"",C25/C44)
B26: POST-PRODUCTION
B27: Editorial (editor + asst.) | C27: 75000 | D27: =IF(C44=0,"",C27/C44) | E27: 75000 | F27: =C27-E27 | G27: ~12-week edit; gear/software
B28: Color Grading / DI | C28: 40000 | D28: =IF(C44=0,"",C28/C44) | E28: 40000 | F28: =C28-E28 | G28: Color correction + finishing
B29: Music Score + Licensing | C29: 35000 | D29: =IF(C44=0,"",C29/C44) | E29: 35000 | F29: =C29-E29 | G29: Composer fee + sync budget
B30: Sound Design / Mix | C30: 30000 | D30: =IF(C44=0,"",C30/C44) | E30: 30000 | F30: =C30-E30 | G30: Sound supervisor + mix sessions
B31: VFX / Title Graphics | C31: 20000 | D31: =IF(C44=0,"",C31/C44) | E31: 20000 | F31: =C31-E31 | G31: Basic VFX; title design
B32: Deliverables (DCP, IMF, etc.) | C32: 20000 | D32: =IF(C44=0,"",C32/C44) | E32: 20000 | F32: =C32-E32 | G32: DCP master + digital deliverables
B33: Closed Captions / Subtitles | C33: 5000 | D33: =IF(C44=0,"",C33/C44) | E33: 5000 | F33: =C33-E33 | G33: Required by all streaming platforms
B34: POST SUBTOTAL | C34: =SUM(C27,C28,C29,C30,C31,C32,C33) | D34: =IF(C44=0,"",C34/C44)
B35: GENERAL & ADMINISTRATIVE
B36: Production + E&O Insurance | C36: 37000 | D36: =IF(C44=0,"",C36/C44) | E36: 37000 | F36: =C36-E36 | G36: Cast, equip., GL, workers comp + E&O
B37: Completion Bond (~2.5%) | C37: 50000 | D37: =IF(C44=0,"",C37/C44) | E37: 50000 | F37: =C37-E37 | G37: Required by gap/debt lenders; ~2-3% total
B38: Legal (entertainment attorney) | C38: 20000 | D38: =IF(C44=0,"",C38/C44) | E38: 20000 | F38: =C38-E38 | G38: PPM, LLC formation, all contracts
B39: Accounting / Production Audit | C39: 15000 | D39: =IF(C44=0,"",C39/C44) | E39: 15000 | F39: =C39-E39 | G39: Production accountant + year-end CPA
B40: Festival Submissions & Fees | C40: 10000 | D40: =IF(C44=0,"",C40/C44) | E40: 10000 | F40: =C40-E40 | G40: Entry fees, screeners, travel
B41: Marketing / PR Seed | C41: 20000 | D41: =IF(C44=0,"",C41/C44) | E41: 20000 | F41: =C41-E41 | G41: Key art, trailer, website, social
...

Sheet 4_Capital_Stack
B2: CAPITAL STACK — Financing Sources, Risk Position & Investor Terms
B3: Financing Layer | C3: Amount ($) | D3: % of Budget | E3: Position | F3: Target Return | G3: Notes
B4: NON-DILUTIVE / SOFT MONEY (Received First)
B5: State Tax Credit / Production Rebate | C5: ='2_Assumptions'!C8 | D5: =IF('2_Assumptions'!C7=0,"",C5/'2_Assumptions'!C7) | E5: Non-dilutive | F5: N/A | G5: Received post-wrap; used to repay tax credit loan
B6: Federal / Intl Co-Pro Incentive | C6: 0 | D6: =IF('2_Assumptions'!C7=0,"",C6/'2_Assumptions'!C7) | E6: Non-dilutive | F6: N/A | G6: Only if co-production treaty applies
B7: Film Fund / Grant | C7: 0 | D7: =IF('2_Assumptions'!C7=0,"",C7/'2_Assumptions'!C7) | E7: Non-dilutive | F7: N/A | G7: Sundance, IFC, regional arts councils, etc.
B8: SOFT MONEY SUBTOTAL | C8: =SUM(C5,C6,C7) | D8: =IF('2_Assumptions'!C7=0,"",C8/'2_Assumptions'!C7)
B9: SENIOR DEBT — FIRST POSITION
B10: Tax Credit Bridge Loan (90% advance) | C10: ='2_Assumptions'!C9 | D10: =IF('2_Assumptions'!C7=0,"",C10/'2_Assumptions'!C7) | E10: 1st Position | F10: ='2_Assumptions'!C20 | G10: Secured on tax credit; repaid upon receipt
B11: Intl Pre-Sale Loan (90% of MGs) | C11: 0 | D11: =IF('2_Assumptions'!C7=0,"",C11/'2_Assumptions'!C7) | E11: 1st Position | F11: 8-12% | G11: Secured against MG contracts; requires sales agent
B12: Domestic MG / Output Deal | C12: 0 | D12: =IF('2_Assumptions'!C7=0,"",C12/'2_Assumptions'!C7) | E12: 1st Position | F12: 8-12% | G12: Domestic advance; uncommon at <$2M
B13: SENIOR DEBT SUBTOTAL | C13: =SUM(C10,C11,C12) | D13: =IF('2_Assumptions'!C7=0,"",C13/'2_Assumptions'!C7)
B14: GAP / MEZZANINE — SECOND POSITION
B15: Gap Loan (against unsold territories) | C15: ='2_Assumptions'!C10 | D15: =IF('2_Assumptions'!C7=0,"",C15/'2_Assumptions'!C7) | E15: 2nd Position | F15: ='2_Assumptions'!C21 | G15: Lender holds security in unsold territory rights
B16: Mezzanine / Subordinated Note | C16: 0 | D16: =IF('2_Assumptions'!C7=0,"",C16/'2_Assumptions'!C7) | E16: 2nd Position | F16: 15-20% | G16: Subordinated to senior debt; pari passu or junior to gap
B17: GAP / MEZZ SUBTOTAL | C17: =SUM(C15,C16) | D17: =IF('2_Assumptions'!C7=0,"",C17/'2_Assumptions'!C7)
B18: EQUITY — THIRD POSITION (At-Risk Capital)
B19: Equity Investor Pool (Class A Members) | C19: ='2_Assumptions'!C12 | D19: =IF('2_Assumptions'!C7=0,"",C19/'2_Assumptions'!C7) | E19: 3rd Position | F19: 120% Hurdle + 50% Backend | G19: See Waterfall sheet for full return mechanics
B20: Producer Deferred / Equity (Class B) | C20: 0 | D20: =IF('2_Assumptions'!C7=0,"",C20/'2_Assumptions'!C7) | E20: 3rd Position | F20: Backend only | G20: Deferred fee converted to equity at close
B21: EQUITY SUBTOTAL | C21: =SUM(C19,C20) | D21: =IF('2_Assumptions'!C7=0,"",C21/'2_Assumptions'!C7)
B22: TOTAL FINANCING | C22: =SUM(C8,C13,C17,C21) | D22: =IF('2_Assumptions'!C7=0,"",C22/'2_Assumptions'!C7) | G22: Must equal Total Production Budget on Assumptions sheet
B24: =IF(ABS(C22-'2_Assumptions'!C7)<1,"✓ Capital stack balances to budget","⚠ MISMATCH — stack $"&TEXT(C22,"#,##0")&" vs budget $"&TEXT('2_Assumptions'!C7,"#,##0"))
B26: INVESTOR TERMS AT A GLANCE
B27: Investment Vehicle | C27: ='2_Assumptions'!C33
B28: Total Equity Raising | C28: ='2_Assumptions'!C12
B29: Min. Investment | C29: ='2_Assumptions'!C14
B30: Investor Class | C30: Class A Limited Members
B31: Recoupment Priority | C31: First from Net Producer Proceeds
B32: Recoupment Premium | C32: ='2_Assumptions'!C17
B33: Backend — Investors | C33: ='2_Assumptions'!C18
B34: Backend — Producer | C34: ='2_Assumptions'!C19
B35: Raise Close Target | C35: ='2_Assumptions'!C32
B36: Legal Exemption | C36: ='2_Assumptions'!C34

Sheet 5_Waterfall
B2: REVENUE WATERFALL & INVESTOR RETURN CALCULATOR | Change C4 to run scenarios
B3: GROSS REVENUE INPUT — Linked from Revenue Model Base Case; override here to run scenarios
B4: Total Gross Revenue — All Windows, All Years | C4: 3500000 | D4: Scenario revenue input — change to model different outcomes
B6: Waterfall Step | C6: Amount ($) | D6: Running Balance ($) | E6: Explanation
B7: ① Gross Revenue (All Windows) | C7: =C4 | D7: =SUM(C7:C7) | E7: Total revenue across all distribution windows and years
B8: ② Less: Exhibitor / Theater Take | C8: =-C4*'2_Assumptions'!C25 | D8: =SUM(C7:C8) | E8: Theaters retain ~50% of theatrical gross
B9: ③ Film Rental (Net of Exhibitor) | C9: =C4*(1-'2_Assumptions'!C25) | D9: =SUM(C7:C9) | E9: Revenue after theater split; enters distribution
B10: ④ Less: P&A / Distribution Costs | C10: =-'2_Assumptions'!C26 | D10: =SUM(C7:C10) | E10: Distributor recoups prints, advertising, and marketing first
B11: ⑤ Less: Distribution Fee | C11: =-(C9-C10)*'2_Assumptions'!C27 | D11: =SUM(C7:C11) | E11: Fee on net film rental (after P&A); per distribution deal
B12: ⑥ Less: Sales Agent Commission | C12: =-C4*'2_Assumptions'!C28 | D12: =SUM(C7:C12) | E12: Sales agent commission on gross foreign receipts
B13: ⑦ NET PRODUCER PROCEEDS | C13: =SUM(C7:C12) | D13: =SUM(C7:C13) | E13: Revenue reaching Production LLC — enters investor waterfall
B14: ⑧ Less: Senior Debt Repayment | C14: =-('2_Assumptions'!C9*(1+'2_Assumptions'!C20)) | D14: =SUM(C7:C14) | E14: Tax credit loan principal + accrued interest
B15: ⑨ Less: Gap / Mezz Repayment | C15: =-('2_Assumptions'!C10*(1+'2_Assumptions'!C21)) | D15: =SUM(C7:C15) | E15: Gap loan principal + interest; 0 if no gap financing used
B16: ⑩ AVAILABLE FOR EQUITY RECOUPMENT | C16: =C13+C14+C15 | D16: =SUM(C7:C16) | E16: Remaining after all debt fully serviced
B17: ⑪ Investor Recoupment (Principal + Premium) | C17: =MIN(MAX(C16,0),'2_Assumptions'!C12*(1+'2_Assumptions'!C17)) | D17: =SUM(C7:C17) | E17: Investors recover principal × (1 + premium); capped at available
B18: ⑫ REMAINING FOR PROFIT SPLIT | C18: =MAX(C16-ABS(C17),0) | D18: =SUM(C7:C18) | E18: Backend pool — flows only if recoupment fully achieved
B19: ⑬ Investor Backend | C19: =C18*'2_Assumptions'!C18 | D19: =SUM(C7:C19) | E19: Investor pool's backend share of remaining proceeds
B20: ⑭ Producer / Filmmaker Backend | C20: =C18*'2_Assumptions'!C19 | D20: =SUM(C7:C20) | E20: Producer's share; distributed to talent and creative team
B23: INVESTOR RETURN SUMMARY
B24: Equity Invested | C24: ='2_Assumptions'!C12 | D24: Change C4 above to model different revenue scenarios
B25: Investor Recoupment (incl. premium) | C25: =ABS(C17)
B26: Investor Backend | C26: =C19
B27: TOTAL INVESTOR RETURN ($) | C27: =ABS(C17)+C19
B28: Net Profit to Investor ($) | C28: =ABS(C17)+C19-'2_Assumptions'!C12
B29: Return Multiple (MOIC) | C29: =(ABS(C17)+C19)/'2_Assumptions'!C12
B30: Simple Cash-on-Cash ROI | C30: =(ABS(C17)+C19-'2_Assumptions'!C12)/'2_Assumptions'!C12
B31: Producer Net Proceeds | C31: =C20
B32: Breakeven Gross Revenue | C32: =('2_Assumptions'!C12*(1+'2_Assumptions'!C17)+'2_Assumptions'!C9*(1+'2_Assumptions'!C20)+'2_Assumptions'!C26+C4*'2_Assumptions'!C28)/((1-'2_Assumptions'!C25)*(1-'2_Assumptions'!C27))
B34: NOTE: Simple ROI does not account for time value of money. IRR will be materially lower over 18-36 month hold periods. Waterfall assumes full recoupment before backend flows; if recoupment not achieved, investors receive available balance only.

Sheet 6_Revenue_Model
B2: REVENUE MODEL — Distribution Windows | Conservative / Base / Upside Scenarios
B3: Revenue Stream / Window | C3: Conservative ($) | D3: Base ($) | E3: Upside ($) | F3: Key Assumptions & Drivers
B4: THEATRICAL — DOMESTIC
B5: Gross Box Office | C5: 800000 | D5: 1800000 | E5: 5000000 | F5: Platform/limited release. Wide = much higher P&A ($1M+). Rare for $2M budget films.
B6: Less: Exhibitor Take (50%) | C6: =-C5*'2_Assumptions'!C25 | D6: =-D5*'2_Assumptions'!C25 | E6: =-E5*'2_Assumptions'!C25 | F6: Calculated from Assumptions (C25); ~50-55% to theaters
B7: Less: P&A / Marketing Recoupment | C7: =-'2_Assumptions'!C26 | D7: =-'2_Assumptions'!C26 | E7: =-'2_Assumptions'!C26 | F7: From Assumptions C26; recouped off the top before fees
B8: Less: Distribution Fee | C8: =-(C5*(1-'2_Assumptions'!C25)-'2_Assumptions'!C26)*'2_Assumptions'!C27 | D8: =-(D5*(1-'2_Assumptions'!C25)-'2_Assumptions'!C26)*'2_Assumptions'!C27 | E8: =-(E5*(1-'2_Assumptions'!C25)-'2_Assumptions'!C26)*'2_Assumptions'!C27 | F8: On net film rental after P&A; from Assumptions C27
B9: Domestic Theatrical NET | C9: =C5+C6+C7+C8 | D9: =D5+D6+D7+D8 | E9: =E5+E6+E7+E8 | F9: Net proceeds flowing to LLC from theatrical
B10: INTERNATIONAL SALES
B11: International MGs (pre-sold) | C11: 50000 | D11: 150000 | E11: 500000 | F11: Minimum guarantees from intl distributors via sales agent
B12: Foreign Sales Overages | C12: 0 | D12: 50000 | E12: 200000 | F12: Overage above MG; only when film overperforms in territory
B13: Less: Sales Agent Commission | C13: =-SUM(C11,C12)*'2_Assumptions'!C28 | D13: =-SUM(D11,D12)*'2_Assumptions'!C28 | E13: =-SUM(E11,E12)*'2_Assumptions'!C28 | F13: From Assumptions C28; ~12% of gross intl receipts
B14: International NET | C14: =C11+C12+C13 | D14: =D11+D12+D13 | E14: =E11+E12+E13 | F14: Net international proceeds to LLC
B15: STREAMING — SVOD
B16: SVOD License Fee (Netflix / Prime / MUBI) | C16: 75000 | D16: 300000 | E16: 1500000 | F16: Festival acquisition flat fee. Softening 2025-26 market. Star-driven premium.
B17: STREAMING — TVOD (Transactional)
B18: TVOD Rental/Purchase (Apple, Amazon, Vudu) | C18: 6000 | D18: 25000 | E18: 90000 | F18: Avg indie ~$4-8K; breakout genre hits can reach $50-100K.
B19: STREAMING — AVOD / FAST
B20: AVOD / FAST Revenue (Tubi, Pluto, Roku) | C20: 4000 | D20: 15000 | E20: 55000 | F20: Ad-share revenue; low per-title but recurring library value
B21: TELEVISION
B22: Domestic TV (Cable / PBS / Premium) | C22: 20000 | D22: 75000 | E22: 300000 | F22: Depends heavily on genre; premium cable for drama/thriller
B23: International TV (via sales agent) | C23: 10000 | D23: 50000 | E23: 200000 | F23: Territory-by-territory license fees; managed via sales agent
B24: ANCILLARY
B25: Educational / Non-Theatrical | C25: 5000 | D25: 15000 | E25: 50000 | F25: Universities, libraries, airlines; modest but recurring
B26: Soundtrack / Merchandise | C26: 0 | D26: 5000 | E26: 25000 | F26: Only material for music-driven or franchise-adjacent titles
B27: TAX INCENTIVE
B28: State Tax Credit / Production Rebate | C28: ='2_Assumptions'!C8 | D28: ='2_Assumptions'!C8 | E28: ='2_Assumptions'!C8 | F28: From Assumptions sheet; same across all scenarios
B29: TOTAL GROSS REVENUE — ALL WINDOWS | C29: =SUM(C5,C9,C11,C12,C14,C16,C18,C20,C22,C23,C25,C26,C28) | D29: =SUM(D5,D9,D11,D12,D14,D16,D18,D20,D22,D23,D25,D26,D28) | E29: =SUM(E5,E9,E11,E12,E14,E16,E18,E20,E22,E23,E25,E26,E28) | F29: Sum of all distribution windows + tax credit
B33: Conservative | C33: =C29
B34: Base | C34: =D29
B35: Upside | C35: =E29

Sheet 7_Cash_Flow
B2: MONTHLY CASH FLOW — Investment through Production to Distribution Proceeds
C3: ← Pre-Production ────── Production ───────── Post-Production ────────────── Distribution ────────────────────── →
B4: Cash Flow Category | C4: Mo 1 | D4: Mo 2 | E4: Mo 3 | F4: Mo 4 | G4: Mo 5 | H4: Mo 6 | I4: Mo 7 | J4: Mo 8 | K4: Mo 9 | L4: Mo 10 | M4: Mo 11 | N4: Mo 12 | O4: Mo 18 | P4: Mo 24+
B5: CAPITAL INFLOWS
B6: Equity Investment Draws | C6: 1040000
B7: Tax Credit Bridge Loan | C7: 360000
B8: Gap / Mezz Loan (if used)
B9: TOTAL INFLOWS | C9: =SUM(C6,C7,C8) | D9: =SUM(D6,D7,D8) | E9: =SUM(E6,E7,E8) | F9: =SUM(F6,F7,F8) | G9: =SUM(G6,G7,G8) | H9: =SUM(H6,H7,H8) | I9: =SUM(I6,I7,I8) | J9: =SUM(J6,J7,J8) | ... P9: =SUM(P6,P7,P8)
B10: PRODUCTION EXPENDITURES
B11: Pre-Production (dev, prep, legal) | C11: 80000 | D11: 120000
B12: Principal Photography | E12: 300000 | F12: 300000 | G12: 200000
B13: Post-Production | G13: 50000 | H13: 200000 | I13: 200000 | J13: 150000
B14: General & Administrative (monthly) | C14: 15000 | D14: 15000 | E14: 15000 | F14: 15000 | G14: 15000 | H14: 15000 | I14: 15000 | J14: 15000 | K14: 5000 | L14: 5000
B15: Completion Bond & Insurance (upfront) | C15: 87000
B16: TOTAL EXPENDITURES | C16: =-SUM(C11,C12,C13,C14,C15) | D16: =-SUM(D11,D12,D13,D14,D15) | E16: =-SUM(E11,E12,E13,E14,E15) | F16: =-SUM(F11,F12,F13,F14,F15) | G16: =-SUM(G11,G12,G13,G14,G15) | H16: =-SUM(H11,H12,H13,H14,H15) | I16: =-SUM(I11,I12,I13,I14,I15) | J16: =-SUM(J11,J12,J13,J14,J15) | ... P16: =-SUM(P11,P12,P13,P14,P15)
B17: DISTRIBUTION PROCEEDS
B18: SVOD / Streaming License Fee | L18: 300000
B19: International MGs (on delivery) | K19: 150000
B20: Theatrical Net Proceeds | L20: 100000 | M20: 200000 | N20: 100000
B21: State Tax Credit Receipt | K21: 400000
B22: TVOD / AVOD / TV (ongoing) | M22: 10000 | N22: 15000 | O22: 20000 | P22: 30000
B23: TOTAL PROCEEDS | C23: =SUM(C18,C19,C20,C21,C22) | D23: =SUM(D18,D19,D20,D21,D22) | E23: =SUM(E18,E19,E20,E21,E22) | F23: =SUM(F18,F19,F20,F21,F22) | G23: =SUM(G18,G19,G20,G21,G22) | H23: =SUM(H18,H19,H20,H21,H22) | I23: =SUM(I18,I19,I20,I21,I22) | J23: =SUM(J18,J19,J20,J21,J22) | ... P23: =SUM(P18,P19,P20,P21,P22)
B24: DEBT REPAYMENT
B25: Tax Credit Bridge Loan Repayment | K25: -392400
B26: Gap Loan Repayment
B27: TOTAL REPAYMENTS | C27: =SUM(C25,C26) | D27: =SUM(D25,D26) | E27: =SUM(E25,E26) | F27: =SUM(F25,F26) | G27: =SUM(G25,G26) | H27: =SUM(H25,H26) | I27: =SUM(I25,I26) | J27: =SUM(J25,J26) | ... P27: =SUM(P25,P26)
B28: NET CASH POSITION | C28: =SUM(C9,C23)+SUM(C16,C27) | D28: =SUM(D9,D23)+SUM(D16,D27) | E28: =SUM(E9,E23)+SUM(E16,E27) | F28: =SUM(F9,F23)+SUM(F16,F27) | G28: =SUM(G9,G23)+SUM(G16,G27) | H28: =SUM(H9,H23)+SUM(H16,H27) | I28: =SUM(I9,I23)+SUM(I16,I27) | J28: =SUM(J9,J23)+SUM(J16,J27) | ... P28: =SUM(P9,P23)+SUM(P16,P27)
B29: CUMULATIVE CASH | C29: =C28 | D29: =C29+D28 | E29: =D29+E28 | F29: =E29+F28 | G29: =F29+G28 | H29: =G29+H28 | I29: =H29+I28 | J29: =I29+J28 | K29: =J29+K28 | ... P29: =O29+P28
B31: Note: Illustrative cash flow only. Actual deployment will vary based on production schedule, distribution deal timing, and loan draw terms. Negative values in expenditures = cash out; positive in proceeds = cash in.

Sheet 8_Sensitivity
B2: SENSITIVITY ANALYSIS — ROI, MOIC & Breakeven by Revenue Scenario
B4: TABLE 1 — Simple Cash-on-Cash ROI by Gross Revenue Scenario (Base Distribution)
B5: Equity Invested ↓ / Gross Revenue → | C5: $500K | D5: $1M | E5: $1.5M | F5: $2.5M | G5: $3.5M | H5: $5M
B6: $600,000 equity | C6: -1 | D6: -1 | E6: -0.734 | F6: -0.004 | G6: 0.463 | H6: 1.0105
B7: $800,000 equity | C7: -1 | D7: -1 | E7: -0.8005 | F7: -0.253 | G7: 0.24725 | H7: 0.657875
B8: $1,040,000 equity | C8: -1 | D8: -1 | E8: -0.84653846 | F8: -0.42538462 | G8: -0.0042307692 | H8: 0.41375
B9: $1,200,000 equity | C9: -1 | D9: -1 | E9: -0.867 | F9: -0.502 | G9: -0.137 | H9: 0.30525
B10: $1,500,000 equity | C10: -1 | D10: -1 | E10: -0.8936 | F10: -0.6016 | G10: -0.3096 | H10: 0.1284
B13: TABLE 2 — Investor MOIC by Gross Revenue & Recoupment Premium ($1.04M equity base)
B14: Recoup Premium ↓ / Revenue → | C14: $500K | D14: $1M | E14: $1.5M | F14: $2.5M | G14: $3.5M | H14: $5M
B15: 10% premium | C15: 0 | D15: 0 | E15: 0.15346154 | F15: 0.57461538 | G15: 0.99576923 | H15: 1.36375
B16: 15% premium | C16: 0 | D16: 0 | E16: 0.15346154 | F16: 0.57461538 | G16: 0.99576923 | H16: 1.38875
B17: 20% premium | C17: 0 | D17: 0 | E17: 0.15346154 | F17: 0.57461538 | G17: 0.99576923 | H17: 1.41375
B18: 25% premium | C18: 0 | D18: 0 | E18: 0.15346154 | F18: 0.57461538 | G18: 0.99576923 | H18: 1.43875
B19: 30% premium | C19: 0 | D19: 0 | E19: 0.15346154 | F19: 0.57461538 | G19: 0.99576923 | H19: 1.46375
B22: TABLE 3 — Estimated Breakeven Gross Revenue Required by Distribution Strategy
B23: Distribution Strategy | C23: Exhibitor % | D23: Distrib. Fee | E23: P&A ($) | F23: SA Comm. | G23: Equity | H23: Breakeven Gross
B24: SVOD-First (No Theatrical) | C24: 0 | D24: 0.25 | E24: 0 | F24: 0.1 | G24: 1040000 | H24: 2524000
B25: Limited Theatrical + SVOD | C25: 0.5 | D25: 0.3 | E25: 150000 | F25: 0.12 | G25: 1040000 | H25: 7784000
B26: Full Theatrical Wide Release | C26: 0.52 | D26: 0.35 | E26: 1000000 | F26: 0.12 | G26: 1040000 | H26: 13752000
B27: International Pre-Sales Only | C27: 0 | D27: 0.2 | E27: 50000 | F27: 0.12 | G27: 1040000 | H27: 2486000
B28: Hybrid (Self-Distributed) | C28: 0.1 | D28: 0.15 | E28: 75000 | F28: 0.05 | G28: 1040000 | H28: 2399000
B30: Note: ROI, MOIC, and breakeven figures are illustrative calculations using simplified assumptions. Actual returns depend on negotiated deal terms, collection account mechanics, hold period, and distribution performance.

Sheet 9_Risk_Register
B2: RISK REGISTER — Investor-Facing Risk Factors & Mitigation Strategies
B3: Risk Factor | C3: Category | D3: Probability | E3: Impact (1-5) | F3: Risk Score | G3: Mitigation | H3: Residual Risk / Status
B4: Completion Risk — Production over budget or fails to complete | C4: Production | D4: 25% | E4: 4 | F4: 1 | G4: Completion bond from recognized provider; 10% contingency in budget; experienced producer | H4: Reduced via bond; monitor weekly burn rate
B5: No Distribution — Film not acquired or finds no distribution deal | C5: Commercial | D5: 40% | E5: 5 | F5: 2 | G5: Attach sales agent pre-production; target A-list festivals; compare to comps with distribution | H5: Build SVOD-first strategy as fallback
B6: Revenue Underperformance — Distribution proceeds insufficient to recoup | C6: Financial | D6: 45% | E6: 5 | F6: 2.2 | G6: Conservative waterfall projections; recoupment priority before any backend; diversified revenue windows | H6: Investors receive pro-rata of available; full loss possible
B7: SVOD Market Contraction — Platform licensing fees decline further | C7: Market | D7: 35% | E7: 4 | F7: 1.4 | G7: Develop multi-window strategy; do not rely solely on one platform; build TVOD + AVOD as base | H7: Multiple fallback windows modeled
B8: Key Person Risk — Director, star, or producer leaves project | C8: Production | D8: 15% | E8: 5 | F8: 0.8 | G8: Cast and key person insurance; attached talent clauses in agreements; backup casting plan | H8: Completion bond may cover; disruption risk remains
B9: Tax Credit Risk — Rebate denied, delayed, or reduced | C9: Financial | D9: 20% | E9: 4 | F9: 0.8 | G9: Work with qualified production tax attorney; obtain pre-approval letter if available; conservative credit estimate | H9: Do not deploy until credit is confirmed
B10: Legal / Chain of Title Issues | C10: Legal | D10: 10% | E10: 5 | F10: 0.5 | G10: Full chain of title clearance before close; E&O insurance; copyright registration; music clearance | H10: E&O policy transfers risk at delivery
B11: Interest Rate / Bridge Loan Risk — Costs exceed projection | C11: Financial | D11: 15% | E11: 3 | F11: 0.4 | G11: Fixed-rate bridge agreement where possible; model sensitivity on Sensitivity sheet | H11: Modeled at 9% senior; 16% gap
B12: Investor Relations Risk — Investor default or early withdrawal | C12: Operational | D12: 10% | E12: 4 | F12: 0.4 | G12: Binding subscription agreements with LLC; PPM disclaims redemption rights; clear closing conditions | H12: No investor withdrawal after subscription signed
B13: Festival Rejection — Film fails to secure marquee premiere | C13: Commercial | D13: 40% | E13: 3 | F13: 1.2 | G13: Direct distribution plan (SVOD-first) as backup; trailer-driven digital release strategy | H13: Box office/SVOD unaffected by festival absent buzz boost
B14: Copyright / Music Clearance Risk | C14: Legal | D14: 20% | E14: 3 | F14: 0.6 | G14: Pre-clear all music before post; use original score; budget for festival print clearances | H14: E&O insurance and music supervisor on board
B15: Currency / Foreign Exchange Risk | C15: Financial | D15: 25% | E15: 3 | F15: 0.8 | G15: Invoice intl pre-sales in USD; use collection account in USD; minimize EUR/GBP exposure | H15: Currency hedging costly at indie budget; accept residual risk
... B17: Technology / Data Loss Risk | C17: Operational | D17: 10% | E17: 3 | F17: 0.3 | G17: Daily cloud backup of all media and data (RAID + offsite); data security protocols during production | H17: Low residual with backup discipline
B19: Risk Score = Probability × Impact (1-5). Red ≥ 2.0, Yellow 1.0-1.9, Green < 1.0. Provide this register in full investor due diligence package (not in first pitch). Revisit quarterly.
