Workbook

Sheet Cover
B2: INDIE FILM FINANCE PLAN
B3: Interactive Model — Google Sheets Compatible
B5: HOW TO USE
B6: 1. Open the Assumptions tab
B7: 2. Edit BLUE cells with your numbers
B8: 3. All other tabs update automatically
B9: 4. Use Waterfall C3 to model revenue scenarios
B10: 5. Upload to Google Sheets — all formulas work
B12: SHEET GUIDE
B13: Assumptions | C13: Master inputs — start here
B14: Budget | C14: Department-level production budget
B15: Capital_Stack | C15: Financing layers + investor terms
B16: Waterfall | C16: Revenue waterfall + return calculator
B17: Revenue_Model | C17: 3-scenario distribution revenue
B18: Sensitivity | C18: ROI matrices + breakeven analysis
B19: Risk_Register | C19: Risk factors + mitigation
B21: COLOR LEGEND
B22: Blue = Input (edit these)
B23: Black = Formula (don't edit)
B24: Green = Cross-sheet link
B26: Not an offer of securities. Consult entertainment attorneys before raising capital.

Sheet Assumptions
B1: MASTER ASSUMPTIONS
B2: Blue = Input | Black = Formula | Green = Cross-Sheet Link
B3: Assumption | C3: Value | D3: Notes | E3: Benchmark
B4: A. PROJECT & BUDGET
B5: Project Title | C5: [PROJECT TITLE] | D5: As it appears in legal docs | E5: —
B6: Genre | C6: [e.g. Thriller] | D6: Drives comparable film selection | E6: —
B7: Total Production Budget ($) | C7: 2000000 | D7: All-in: ATL+BTL+Post+G&A+Bond+Contingency | E7: $500K–$10M
B8: State Tax Credit / Rebate (%) | C8: 0.2 | D8: % qualifying in-state spend | E8: 20%–45%
B9: Tax Credit Loan Advance (%) | C9: 0.9 | D9: 90% advance on tax credit | E9: 90% typical
B10: Gap / Mezz Financing ($) | C10: 0 | D10: Second-position; only if needed | E10: 0–15% of budget
B11: Pre-Sale Loan ($) | C11: 0 | D11: Against executed MG contracts | E11: 0–20% at $2M+
B12: Min. Investment / Investor ($) | C12: 50000 | D12: Reg D 506(b) accredited | E12: $25K–$100K
B14: AUTO-CALCULATED
B15: Tax Credit Amount ($) | C15: =C7*C8 -> 400000 | D15: Budget × Tax Credit % | E15: Auto
B16: Senior Debt — TC Loan ($) | C16: =C15*C9 -> 360000 | D16: Tax Credit × Loan Advance % | E16: Auto
B17: TOTAL EQUITY RAISE ($) | C17: =MAX(0,C7-C16-C10-C11) -> 1640000 | D17: Budget minus all debt = equity needed from investors | E17: Auto
B18: Est. # of Investors | C18: =IF(C12>0,ROUNDUP(C17/C12,0),0) -> 33 | D18: Equity ÷ Min Investment | E18: 5–30 typical
B20: B. INVESTOR TERMS & WATERFALL
B21: Recoupment Premium (%) | C21: 0.2 | D21: % above principal before backend | E21: 15%–25%
B22: Investor Backend Split (%) | C22: 0.5 | D22: % of net profit after hurdle | E22: 40%–50%
B23: Producer Backend Split (%) | C23: =1-C22 -> 0.5 | D23: Auto: 1 minus investor split | E23: Auto
B24: Senior Debt Interest Rate | C24: 0.09 | D24: Tax credit bridge | E24: 8%–12%
B25: Gap Loan Interest Rate | C25: 0.16 | D25: Higher risk capital | E25: 12%–20%
B26: Loan Term (months) | C26: 18 | D26: Bridge to distribution receipt | E26: 12–36 months
B28: C. DISTRIBUTION ASSUMPTIONS
B29: Exhibitor / Theater Split (%) | C29: 0.5 | D29: Theaters retain ~50–55% | E29: 45%–55%
B30: P&A / Marketing Budget ($) | C30: 150000 | D30: Recouped before commissions | E30: $50K–$2M+
B31: Distribution Fee (%) | C31: 0.3 | D31: On net film rental | E31: 25%–35%
B32: Sales Agent Commission (%) | C32: 0.12 | D32: On gross foreign receipts | E32: 10%–15%
B34: D. LEGAL & TIMELINE
B35: Raise Close Target | C35: Q2 2026
B36: Legal Vehicle | C36: Single-Purpose LLC
B37: Securities Exemption | C37: Reg D / Rule 506(b)
B38: PPM Required? | C38: Yes — Attorney Drafted
B39: SAG-AFTRA Tier | C39: Modified Low Budget
B40: E&O Insurance | C40: $1,000,000

Sheet Budget
B1: PRODUCTION BUDGET — Top Sheet
B2: Line Item | C2: Budget ($) | D2: % Total | E2: Prior Est. | F2: Variance | G2: Notes
B3: ABOVE THE LINE
B4: Story & Rights | C4: 40000 | D4: =C4/Assumptions!C7 -> 0.02 | E4: 40000 | F4: =C4-E4 -> 0 | G4: Option on IP rights
B5: Screenplay | C5: 25000 | D5: =C5/Assumptions!C7 -> 0.0125 | E5: 25000 | F5: =C5-E5 -> 0 | G5: WGA min or negotiated
B6: Producer(s) Fee | C6: 60000 | D6: =C6/Assumptions!C7 -> 0.03 | E6: 60000 | F6: =C6-E6 -> 0 | G6: Deferral common
B7: Director Fee | C7: 100000 | D7: =C7/Assumptions!C7 -> 0.05 | E7: 100000 | F7: =C7-E7 -> 0 | G7: DGA or non-union
B8: Lead Cast | C8: 200000 | D8: =C8/Assumptions!C7 -> 0.1 | E8: 200000 | F8: =C8-E8 -> 0 | G8: SAG Modified Low Budget
B9: Supporting Cast | C9: 50000 | D9: =C9/Assumptions!C7 -> 0.025 | E9: 50000 | F9: =C9-E9 -> 0 | G9: Day players
B10: ABOVE SUBTOTAL | C10: =SUM(C4:C9) -> 475000 | D10: =C10/Assumptions!C7 -> 0.2375
B12: BELOW THE LINE — PRODUCTION
B13: 1st AD / Staff | C13: 35000 | D13: =C13/Assumptions!C7 -> 0.0175 | E13: 35000 | F13: =C13-E13 -> 0 | G13: Coordinators+PAs
B14: Camera | C14: 80000 | D14: =C14/Assumptions!C7 -> 0.04 | E14: 80000 | F14: =C14-E14 -> 0 | G14: DP+package+lenses
B15: Grip & Electric | C15: 120000 | D15: =C15/Assumptions!C7 -> 0.06 | E15: 120000 | F15: =C15-E15 -> 0 | G15: Gaffer,grip,truck
B16: Art Dept | C16: 90000 | D16: =C16/Assumptions!C7 -> 0.045 | E16: 90000 | F16: =C16-E16 -> 0 | G16: PD,set dec,props
B17: Wardrobe | C17: 35000 | D17: =C17/Assumptions!C7 -> 0.0175 | E17: 35000 | F17: =C17-E17 -> 0 | G17: Costumes,rentals
B18: Hair & Makeup | C18: 28000 | D18: =C18/Assumptions!C7 -> 0.014 | E18: 28000 | F18: =C18-E18 -> 0 | G18: Key MUA+hair
B19: Sound | C19: 22000 | D19: =C19/Assumptions!C7 -> 0.011 | E19: 22000 | F19: =C19-E19 -> 0 | G19: Mixer,boom,kit
B20: Locations | C20: 65000 | D20: =C20/Assumptions!C7 -> 0.0325 | E20: 65000 | F20: =C20-E20 -> 0 | G20: Fees,scouts,permits
B21: Transportation | C21: 55000 | D21: =C21/Assumptions!C7 -> 0.0275 | E21: 55000 | F21: =C21-E21 -> 0 | G21: Trucks,base camp
B22: Catering | C22: 40000 | D22: =C22/Assumptions!C7 -> 0.02 | E22: 40000 | F22: =C22-E22 -> 0 | G22: ~30 days
B23: Extras | C23: 18000 | D23: =C23/Assumptions!C7 -> 0.009 | E23: 18000 | F23: =C23-E23 -> 0 | G23: Featured+BG
B24: Stunts | C24: 15000 | D24: =C24/Assumptions!C7 -> 0.0075 | E24: 15000 | F24: =C24-E24 -> 0 | G24: Coordinator+personnel
B25: BELOW SUBTOTAL | C25: =SUM(C13:C24) -> 603000 | D25: =C25/Assumptions!C7 -> 0.3015
B27: POST-PRODUCTION
B28: Editorial | C28: 75000 | D28: =C28/Assumptions!C7 -> 0.0375 | E28: 75000 | F28: =C28-E28 -> 0 | G28: ~12-week edit
B29: Color/DI | C29: 40000 | D29: =C29/Assumptions!C7 -> 0.02 | E29: 40000 | F29: =C29-E29 -> 0 | G29: Correction+finishing
B30: Music | C30: 35000 | D30: =C30/Assumptions!C7 -> 0.0175 | E30: 35000 | F30: =C30-E30 -> 0 | G30: Composer+sync
B31: Sound Design/Mix | C31: 30000 | D31: =C31/Assumptions!C7 -> 0.015 | E31: 30000 | F31: =C31-E31 -> 0 | G31: Supervisor+sessions
B32: VFX/Titles | C32: 20000 | D32: =C32/Assumptions!C7 -> 0.01 | E32: 20000 | F32: =C32-E32 -> 0 | G32: Basic VFX
B33: Deliverables | C33: 20000 | D33: =C33/Assumptions!C7 -> 0.01 | E33: 20000 | F33: =C33-E33 -> 0 | G33: DCP+digital
B34: Captions | C34: 5000 | D34: =C34/Assumptions!C7 -> 0.0025 | E34: 5000 | F34: =C34-E34 -> 0 | G34: Required by platforms
B35: POST-PRODUCTION SUBTOTAL | C35: =SUM(C28:C34) -> 225000 | D35: =C35/Assumptions!C7 -> 0.1125
B37: GENERAL & ADMINISTRATIVE
B38: Insurance+E&O | C38: 37000 | D38: =C38/Assumptions!C7 -> 0.0185 | E38: 37000 | F38: =C38-E38 -> 0 | G38: Cast,equip,GL,WC,E&O
B39: Completion Bond | C39: 50000 | D39: =C39/Assumptions!C7 -> 0.025 | E39: 50000 | F39: =C39-E39 -> 0 | G39: ~2.5% for lenders
B40: Legal | C40: 20000 | D40: =C40/Assumptions!C7 -> 0.01 | E40: 20000 | F40: =C40-E40 -> 0 | G40: PPM,LLC,contracts
B41: Accounting | C41: 15000 | D41: =C41/Assumptions!C7 -> 0.0075 | E41: 15000 | F41: =C41-E41 -> 0 | G41: Prod accountant+CPA
B42: Festivals | C42: 10000 | D42: =C42/Assumptions!C7 -> 0.005 | E42: 10000 | F42: =C42-E42 -> 0 | G42: Entries,screeners
B43: Marketing Seed | C43: 20000 | D43: =C43/Assumptions!C7 -> 0.01 | E43: 20000 | F43: =C43-E43 -> 0 | G43: Key art,trailer,social
...

Sheet Capital_Stack
B1: CAPITAL STACK
B2: Layer | C2: Amount ($) | D2: % Budget | E2: Position | F2: Return | G2: Notes
B3: SOFT MONEY
B4: Tax Credit/Rebate | C4: =Assumptions!C15 -> 400000 | D4: =C4/Assumptions!C7 -> 0.2 | E4: Non-dilutive | F4: N/A | G4: Received post-wrap
B6: SENIOR DEBT
B7: Tax Credit Bridge Loan | C7: =Assumptions!C16 -> 360000 | D7: =C7/Assumptions!C7 -> 0.18 | E7: 1st Position | F7: =Assumptions!C24 -> 0.09 | G7: Secured on credit
B9: GAP/MEZZ
B10: Gap Loan | C10: =Assumptions!C10 -> 0 | D10: =C10/Assumptions!C7 -> 0 | E10: 2nd Position | F10: =Assumptions!C25 -> 0.16 | G10: If needed
B12: EQUITY
B13: Investor Pool (Class A) | C13: =Assumptions!C17 -> 1640000 | D13: =C13/Assumptions!C7 -> 0.82 | E13: 3rd Position | F13: Hurdle+Backend | G13: At-risk capital
B16: TOTAL FINANCING | C16: C4+C7+C10+C13

Sheet Waterfall
B1: REVENUE WATERFALL & INVESTOR RETURN CALCULATOR
B3: GROSS REVENUE INPUT | C3: 3500000 | D3: ← Change to model scenarios
B5: Step | C5: Amount ($) | D5: Running Balance ($) | E5: Explanation
B6: ① Gross Revenue | C6: =C3 -> 3500000 | D6: =C3 -> 3500000 | E6: Total revenue all windows
B7: ② Less: Exhibitor Take | C7: =C3*0.5*Assumptions!C29 -> 875000 | D7: =D6-C7 -> 2625000 | E7: Theaters retain ~50%
B8: ③ Film Rental | C8: =D7 -> 2625000 | D8: =D7 -> 2625000 | E8: Net of exhibitor
B9: ④ Less: P&A | C9: =Assumptions!C30 -> 150000 | D9: =D8-C9 -> 2475000 | E9: Recouped first
B10: ⑤ Less: Distribution Fee | C10: =MAX(0,D9)*Assumptions!C31 -> 742500 | D10: =D9-C10 -> 1732500 | E10: On net film rental
B11: ⑥ Less: SA Commission | C11: =C3*0.3*Assumptions!C32 -> 126000 | D11: =D10-C11 -> 1606500 | E11: On intl portion ~30%
B12: ⑦ NET PRODUCER PROCEEDS | C12: =MAX(0,D11) -> 1606500 | D12: =C12 -> 1606500 | E12: Enters investor waterfall
B13: ⑧ Less: Senior Debt | C13: =Assumptions!C16*(1+Assumptions!C24*Assumptions!C26/12) -> 408600 | D13: =MAX(0,D12-C13) -> 1197900 | E13: Principal + interest
B14: ⑨ Less: Gap Repayment | C14: =Assumptions!C10*(1+Assumptions!C25*Assumptions!C26/12) -> 0 | D14: =MAX(0,D13-C14) -> 1197900 | E14: Gap + interest
B15: ⑩ Available for Equity | C15: =D14 -> 1197900 | D15: =D14 -> 1197900 | E15: After all debt
B16: ⑪ Investor Recoupment | C16: =MIN(Assumptions!C17*(1+Assumptions!C21),D15) -> 1197900 | D16: =MAX(0,D15-C16) -> 0 | E16: Capped at available
B17: ⑫ Remaining for Split | C17: =D16 -> 0 | D17: =D16 -> 0 | E17: Backend pool
B18: ⑬ Investor Backend | C18: =D17*Assumptions!C22 -> 0 | D18: =D17-C18 -> 0 | E18: Investor share
B19: ⑭ Producer Backend | C19: =D18 -> 0 | D19: =0 -> 0 | E19: Producer share
B21: INVESTOR RETURN SUMMARY
B22: Equity Invested | C22: =Assumptions!C17 -> 1640000
B23: Investor Recoupment | C23: =C16 -> 1197900
B24: Investor Backend | C24: =C18 -> 0
B25: TOTAL INVESTOR RETURN | C25: =C23+C24 -> 1197900
B26: Net Profit to Investor | C26: =C25-C22 -> -442100
B27: MOIC | C27: =IF(C22>0,C25/C22,0) -> 0.73042683
B28: ROI (Cash-on-Cash) | C28: =IF(C22>0,(C25-C22)/C22,0) -> -0.26957317
B29: Producer Net Proceeds | C29: =C19 -> 0

Sheet Revenue_Model
B1: REVENUE MODEL — Conservative / Base / Upside
B2: Window | C2: Conservative | D2: Base | E2: Upside | F2: Notes
B3: THEATRICAL — DOMESTIC
B4: Gross Box Office | C4: 800000 | D4: 1800000 | E4: 5000000 | F4: Platform/limited release
B5: Less: Exhibitor | C5: =-C4*Assumptions!C29 -> -400000 | D5: =-D4*Assumptions!C29 -> -900000 | E5: =-E4*Assumptions!C29 -> -2500000 | F5: ~50% to theaters
B6: Less: P&A | C6: =-Assumptions!C30 -> -150000 | D6: =-Assumptions!C30 -> -150000 | E6: =-Assumptions!C30 -> -150000 | F6: Off the top
B7: Less: Dist Fee | C7: =-MAX(0,C4+C5+C6)*Assumptions!C31 -> -75000 | D7: =-MAX(0,D4+D5+D6)*Assumptions!C31 -> -225000 | E7: =-MAX(0,E4+E5+E6)*Assumptions!C31 -> -705000 | F7: On net rental
B8: Theatrical NET | C8: =SUM(C4:C7) -> 175000 | D8: =SUM(D4:D7) -> 525000 | E8: =SUM(E4:E7) -> 1645000 | F8: Net to LLC
B9: INTERNATIONAL
B10: International MGs | C10: 50000 | D10: 150000 | E10: 500000 | F10: Via sales agent
B11: Foreign Overages | C11: 0 | D11: 50000 | E11: 200000 | F11: Above MG
B12: Less: SA Commission | C12: =-(C10+C11)*Assumptions!C32 -> -6000 | D12: =-(D10+D11)*Assumptions!C32 -> -24000 | E12: =-(E10+E11)*Assumptions!C32 -> -84000 | F12: ~12% intl
B13: International NET | C13: =SUM(C10:C12) -> 44000 | D13: =SUM(D10:D12) -> 176000 | E13: =SUM(E10:E12) -> 616000 | F13: Net intl
B14: STREAMING
B15: SVOD License Fee | C15: 75000 | D15: 300000 | E15: 1500000 | F15: Festival acquisition
B16: TVOD Rental/Purchase | C16: 6000 | D16: 25000 | E16: 90000 | F16: Avg indie $4-8K
B17: AVOD / FAST | C17: 4000 | D17: 15000 | E17: 55000 | F17: Ad-share revenue
B18: TELEVISION
B19: Domestic TV | C19: 20000 | D19: 75000 | E19: 300000 | F19: Cable/PBS/Premium
B20: International TV | C20: 10000 | D20: 50000 | E20: 200000 | F20: Territory-by-territory
B21: ANCILLARY
B22: Educational/Non-Theatrical | C22: 5000 | D22: 15000 | E22: 50000 | F22: Universities,airlines
B23: Merchandise | C23: 0 | D23: 5000 | E23: 25000 | F23: Music-driven only
B24: TAX INCENTIVE
B25: State Tax Credit | C25: =Assumptions!C15 -> 400000 | D25: =Assumptions!C15 -> 400000 | E25: =Assumptions!C15 -> 400000 | F25: Same all scenarios
B27: TOTAL GROSS REVENUE | C27: =C8+C13+C15+C16+C17+C19+C20+C22+C23+C24 -> 339000 | D27: =D8+D13+D15+D16+D17+D19+D20+D22+D23+D24 -> 1186000 | E27: =E8+E13+E15+E16+E17+E19+E20+E22+E23+E24 -> 4481000

Sheet Sensitivity
B1: SENSITIVITY ANALYSIS
B3: TABLE 1 — ROI by Gross Revenue
B4: Equity ↓ / Revenue → | C4: 500000 | D4: 1000000 | E4: 1500000 | F4: 2500000 | G4: 3500000 | H4: 5000000
B5: 600000 | C5: =IF(600000>0,(MIN(600000*(1+Assumptions!C21),C20)+MAX(0,C20-600000*(1+Assumptions!C21))*Assumptions!C22-600000)/600000,-1) -> -1 | D5: =IF(600000>0,(MIN(600000*(1+Assumptions!C21),D20)+MAX(0,D20-600000*(1+Assumptions!C21))*Assumptions!C22-600000)/600000,-1) -> -1 | E5: =IF(600000>0,(MIN(600000*(1+Assumptions!C21),E20)+MAX(0,E20-600000*(1+Assumptions!C21))*Assumptions!C22-600000)/600000,-1) -> -0.6335 | F5: =IF(600000>0,(MIN(600000*(1+Assumptions!C21),F20)+MAX(0,F20-600000*(1+Assumptions!C21))*Assumptions!C22-600000)/600000,-1) -> 0.1815 | G5: =IF(600000>0,(MIN(600000*(1+Assumptions!C21),G20)+MAX(0,G20-600000*(1+Assumptions!C21))*Assumptions!C22-600000)/600000,-1) -> 0.59825 | H5: =IF(600000>0,(MIN(600000*(1+Assumptions!C21),H20)+MAX(0,H20-600000*(1+Assumptions!C21))*Assumptions!C22-600000)/600000,-1) -> 1.2095
B6: 800000 | C6: =IF(800000>0,(MIN(800000*(1+Assumptions!C21),C20)+MAX(0,C20-800000*(1+Assumptions!C21))*Assumptions!C22-800000)/800000,-1) -> -1 | D6: =IF(800000>0,(MIN(800000*(1+Assumptions!C21),D20)+MAX(0,D20-800000*(1+Assumptions!C21))*Assumptions!C22-800000)/800000,-1) -> -1 | E6: =IF(800000>0,(MIN(800000*(1+Assumptions!C21),E20)+MAX(0,E20-800000*(1+Assumptions!C21))*Assumptions!C22-800000)/800000,-1) -> -0.725125 | F6: =IF(800000>0,(MIN(800000*(1+Assumptions!C21),F20)+MAX(0,F20-800000*(1+Assumptions!C21))*Assumptions!C22-800000)/800000,-1) -> -0.113875 | G6: =IF(800000>0,(MIN(800000*(1+Assumptions!C21),G20)+MAX(0,G20-800000*(1+Assumptions!C21))*Assumptions!C22-800000)/800000,-1) -> 0.3486875 | H6: =IF(800000>0,(MIN(800000*(1+Assumptions!C21),H20)+MAX(0,H20-800000*(1+Assumptions!C21))*Assumptions!C22-800000)/800000,-1) -> 0.807125
B7: 1040000 | C7: =IF(1040000>0,(MIN(1040000*(1+Assumptions!C21),C20)+MAX(0,C20-1040000*(1+Assumptions!C21))*Assumptions!C22-1040000)/1040000,-1) -> -1 | D7: =IF(1040000>0,(MIN(1040000*(1+Assumptions!C21),D20)+MAX(0,D20-1040000*(1+Assumptions!C21))*Assumptions!C22-1040000)/1040000,-1) -> -1 | E7: =IF(1040000>0,(MIN(1040000*(1+Assumptions!C21),E20)+MAX(0,E20-1040000*(1+Assumptions!C21))*Assumptions!C22-1040000)/1040000,-1) -> -0.78855769 | F7: =IF(1040000>0,(MIN(1040000*(1+Assumptions!C21),F20)+MAX(0,F20-1040000*(1+Assumptions!C21))*Assumptions!C22-1040000)/1040000,-1) -> -0.31836538 | G7: =IF(1040000>0,(MIN(1040000*(1+Assumptions!C21),G20)+MAX(0,G20-1040000*(1+Assumptions!C21))*Assumptions!C22-1040000)/1040000,-1) -> 0.15182692 | H7: =IF(1040000>0,(MIN(1040000*(1+Assumptions!C21),H20)+MAX(0,H20-1040000*(1+Assumptions!C21))*Assumptions!C22-1040000)/1040000,-1) -> 0.52855769
B8: 1200000 | C8: =IF(1200000>0,(MIN(1200000*(1+Assumptions!C21),C20)+MAX(0,C20-1200000*(1+Assumptions!C21))*Assumptions!C22-1200000)/1200000,-1) -> -1 | D8: =IF(1200000>0,(MIN(1200000*(1+Assumptions!C21),D20)+MAX(0,D20-1200000*(1+Assumptions!C21))*Assumptions!C22-1200000)/1200000,-1) -> -1 | E8: =IF(1200000>0,(MIN(1200000*(1+Assumptions!C21),E20)+MAX(0,E20-1200000*(1+Assumptions!C21))*Assumptions!C22-1200000)/1200000,-1) -> -0.81675 | F8: =IF(1200000>0,(MIN(1200000*(1+Assumptions!C21),F20)+MAX(0,F20-1200000*(1+Assumptions!C21))*Assumptions!C22-1200000)/1200000,-1) -> -0.40925 | G8: =IF(1200000>0,(MIN(1200000*(1+Assumptions!C21),G20)+MAX(0,G20-1200000*(1+Assumptions!C21))*Assumptions!C22-1200000)/1200000,-1) -> -0.00175 | H8: =IF(1200000>0,(MIN(1200000*(1+Assumptions!C21),H20)+MAX(0,H20-1200000*(1+Assumptions!C21))*Assumptions!C22-1200000)/1200000,-1) -> 0.40475
B9: 1500000 | C9: =IF(1500000>0,(MIN(1500000*(1+Assumptions!C21),C20)+MAX(0,C20-1500000*(1+Assumptions!C21))*Assumptions!C22-1500000)/1500000,-1) -> -1 | D9: =IF(1500000>0,(MIN(1500000*(1+Assumptions!C21),D20)+MAX(0,D20-1500000*(1+Assumptions!C21))*Assumptions!C22-1500000)/1500000,-1) -> -1 | E9: =IF(1500000>0,(MIN(1500000*(1+Assumptions!C21),E20)+MAX(0,E20-1500000*(1+Assumptions!C21))*Assumptions!C22-1500000)/1500000,-1) -> -0.8534 | F9: =IF(1500000>0,(MIN(1500000*(1+Assumptions!C21),F20)+MAX(0,F20-1500000*(1+Assumptions!C21))*Assumptions!C22-1500000)/1500000,-1) -> -0.5274 | G9: =IF(1500000>0,(MIN(1500000*(1+Assumptions!C21),G20)+MAX(0,G20-1500000*(1+Assumptions!C21))*Assumptions!C22-1500000)/1500000,-1) -> -0.2014 | H9: =IF(1500000>0,(MIN(1500000*(1+Assumptions!C21),H20)+MAX(0,H20-1500000*(1+Assumptions!C21))*Assumptions!C22-1500000)/1500000,-1) -> 0.2438
B11: HELPER (base equity calculations)
B12: Gross Revenue | C12: 500000 | D12: 1000000 | E12: 1500000 | F12: 2500000 | G12: 3500000 | H12: 5000000
B13: Exhibitor Take | C13: =C12*0.5*Assumptions!C29 -> 125000 | D13: =D12*0.5*Assumptions!C29 -> 250000 | E13: =E12*0.5*Assumptions!C29 -> 375000 | F13: =F12*0.5*Assumptions!C29 -> 625000 | G13: =G12*0.5*Assumptions!C29 -> 875000 | H13: =H12*0.5*Assumptions!C29 -> 1250000
B14: Film Rental | C14: =C12-C13 -> 375000 | D14: =D12-D13 -> 750000 | E14: =E12-E13 -> 1125000 | F14: =F12-F13 -> 1875000 | G14: =G12-G13 -> 2625000 | H14: =H12-H13 -> 3750000
B15: P&A | C15: =Assumptions!C30 -> 150000 | D15: =Assumptions!C30 -> 150000 | E15: =Assumptions!C30 -> 150000 | F15: =Assumptions!C30 -> 150000 | G15: =Assumptions!C30 -> 150000 | H15: =Assumptions!C30 -> 150000
B16: Dist Fee | C16: =MAX(0,C14-C15)*Assumptions!C31 -> 67500 | D16: =MAX(0,D14-D15)*Assumptions!C31 -> 180000 | E16: =MAX(0,E14-E15)*Assumptions!C31 -> 292500 | F16: =MAX(0,F14-F15)*Assumptions!C31 -> 517500 | G16: =MAX(0,G14-G15)*Assumptions!C31 -> 742500 | H16: =MAX(0,H14-H15)*Assumptions!C31 -> 1080000
B17: SA Comm | C17: =C12*0.3*Assumptions!C32 -> 18000 | D17: =D12*0.3*Assumptions!C32 -> 36000 | E17: =E12*0.3*Assumptions!C32 -> 54000 | F17: =F12*0.3*Assumptions!C32 -> 90000 | G17: =G12*0.3*Assumptions!C32 -> 126000 | H17: =H12*0.3*Assumptions!C32 -> 180000
B18: NPP | C18: =MAX(0,C14-C15-C16-C17) -> 139500 | D18: =MAX(0,D14-D15-D16-D17) -> 384000 | E18: =MAX(0,E14-E15-E16-E17) -> 628500 | F18: =MAX(0,F14-F15-F16-F17) -> 1117500 | G18: =MAX(0,G14-G15-G16-G17) -> 1606500 | H18: =MAX(0,H14-H15-H16-H17) -> 2340000
B19: Debt Repay | C19: =Assumptions!C16*(1+Assumptions!C24*Assumptions!C26/12) -> 408600 | D19: =Assumptions!C16*(1+Assumptions!C24*Assumptions!C26/12) -> 408600 | E19: =Assumptions!C16*(1+Assumptions!C24*Assumptions!C26/12) -> 408600 | F19: =Assumptions!C16*(1+Assumptions!C24*Assumptions!C26/12) -> 408600 | G19: =Assumptions!C16*(1+Assumptions!C24*Assumptions!C26/12) -> 408600 | H19: =Assumptions!C16*(1+Assumptions!C24*Assumptions!C26/12) -> 408600
B20: After Debt | C20: =MAX(0,C18-C19) -> 0 | D20: =MAX(0,D18-D19) -> 0 | E20: =MAX(0,E18-E19) -> 219900 | F20: =MAX(0,F18-F19) -> 708900 | G20: =MAX(0,G18-G19) -> 1197900 | H20: =MAX(0,H18-H19) -> 1931400
B22: TABLE 2 — Breakeven by Distribution Strategy
B23: Strategy | C23: Exhib% | D23: DistFee | E23: P&A | F23: SA% | G23: Equity | H23: Breakeven
B24: SVOD-First | C24: 0 | D24: 0.25 | E24: 0 | F24: 0.1 | G24: =Assumptions!C17 -> 1640000 | H24: =IF((1-C24*0.5)*(1-D24)*(1-F24*0.3)>0,(G24*(1+Assumptions!C21)+Assumptions!C16*(1+Assumptions!C24*Assumptions!C26/12)+E24)/((1-C24*0.5)*(1-D24)*(1-F24*0.3)),0) -> 3266804.1
B25: Limited Theatrical | C25: =Assumptions!C29 -> 0.5 | D25: =Assumptions!C31 -> 0.3 | E25: =Assumptions!C30 -> 150000 | F25: =Assumptions!C32 -> 0.12 | G25: =Assumptions!C17 -> 1640000 | H25: =IF((1-C25*0.5)*(1-D25)*(1-F25*0.3)>0,(G25*(1+Assumptions!C21)+Assumptions!C16*(1+Assumptions!C24*Assumptions!C26/12)+E25)/((1-C25*0.5)*(1-D25)*(1-F25*0.3)),0) -> 4992294
B26: Wide Release | C26: 0.52 | D26: 0.35 | E26: 1000000 | F26: 0.12 | G26: =Assumptions!C17 -> 1640000 | H26: =IF((1-C26*0.5)*(1-D26)*(1-F26*0.3)>0,(G26*(1+Assumptions!C21)+Assumptions!C16*(1+Assumptions!C24*Assumptions!C26/12)+E26)/((1-C26*0.5)*(1-D26)*(1-F26*0.3)),0) -> 7282114.5
B27: Intl Pre-Sales Only | C27: 0 | D27: 0.2 | E27: 50000 | F27: 0.12 | G27: =Assumptions!C17 -> 1640000 | H27: =IF((1-C27*0.5)*(1-D27)*(1-F27*0.3)>0,(G27*(1+Assumptions!C21)+Assumptions!C16*(1+Assumptions!C24*Assumptions!C26/12)+E27)/((1-C27*0.5)*(1-D27)*(1-F27*0.3)),0) -> 3146524.9
B28: Hybrid/Self | C28: 0.1 | D28: 0.15 | E28: 75000 | F28: 0.05 | G28: =Assumptions!C17 -> 1640000 | H28: =IF((1-C28*0.5)*(1-D28)*(1-F28*0.3)>0,(G28*(1+Assumptions!C21)+Assumptions!C16*(1+Assumptions!C24*Assumptions!C26/12)+E28)/((1-C28*0.5)*(1-D28)*(1-F28*0.3)),0) -> 3082271.2

Sheet Risk_Register
B1: RISK REGISTER
B2: Risk Factor | C2: Category | D2: Probability | E2: Impact | F2: Score | G2: Mitigation | H2: Residual
B3: Completion Risk | C3: Production | D3: 0.25 | E3: 4 | F3: =D3*E3 -> 1 | G3: Bond+contingency+experienced producer | H3: Monitor burn rate
B4: No Distribution | C4: Commercial | D4: 0.4 | E4: 5 | F4: =D4*E4 -> 2 | G4: Sales agent pre-prod; A-list festivals | H4: SVOD-first fallback
B5: Revenue Under | C5: Financial | D5: 0.45 | E5: 5 | F5: =D5*E5 -> 2.25 | G5: Conservative projections; diversified windows | H5: Full loss possible
B6: SVOD Contraction | C6: Market | D6: 0.35 | E6: 4 | F6: =D6*E6 -> 1.4 | G6: Multi-window; don't rely on one platform | H6: Fallbacks modeled
B7: Key Person Risk | C7: Production | D7: 0.15 | E7: 5 | F7: =D7*E7 -> 0.75 | G7: Cast insurance; key person clauses | H7: Bond may cover
B8: Tax Credit Risk | C8: Financial | D8: 0.2 | E8: 4 | F8: =D8*E8 -> 0.8 | G8: Qualified tax attorney; pre-approval | H8: Don't deploy early
B9: Chain of Title | C9: Legal | D9: 0.1 | E9: 5 | F9: =D9*E9 -> 0.5 | G9: Full clearance; E&O; copyright reg | H9: E&O transfers risk
B10: Bridge Loan Rate | C10: Financial | D10: 0.15 | E10: 3 | F10: =D10*E10 -> 0.45 | G10: Fixed-rate; sensitivity modeled | H10: Modeled at 9%
B11: Investor Default | C11: Operational | D11: 0.1 | E11: 4 | F11: =D11*E11 -> 0.4 | G11: Binding subscription; PPM disclaims | H11: No withdrawal
B12: Festival Rejection | C12: Commercial | D12: 0.4 | E12: 3 | F12: =D12*E12 -> 1.2 | G12: Direct distribution backup | H12: SVOD unaffected
B13: Music Clearance | C13: Legal | D13: 0.2 | E13: 3 | F13: =D13*E13 -> 0.6 | G13: Pre-clear; original score; budget | H13: E&O+supervisor
B14: FX Risk | C14: Financial | D14: 0.25 | E14: 3 | F14: =D14*E14 -> 0.75 | G14: Invoice USD; CAMA in USD | H14: Accept residual
... B16: Data Loss | C16: Operational | D16: 0.1 | E16: 3 | F16: =D16*E16 -> 0.3 | G16: Daily backup; RAID+offsite | H16: Low with discipline
B18: Score = Prob × Impact. Red ≥ 2.0 | Yellow 1.0–1.9 | Green < 1.0
